Workbook
Name areas: Setores!$B$4:$B$23

Sheet MENU
B1: ANÁLISE POLÍTICA, ECONÔMICA, SOCIAL E TECNOLÓGICA (PEST)
B3: 1.0 | C3: INFORMAÇÕES PRELIMINARES | E3: Insira informações básicas sobre o negócio e os participantes.
B5: 2.0 | C5: PROCESSO DE ANÁLISE | E5: Insira dados referentes a cada fator e inicie o processo de análise, indicando a importância, a intensidade e a tendência
B7: 3.0 | C7: MATRIZ PEST | E7: Observe na matriz quais são os itens que necessitam de maior atenção. Essas informações são essenciais para o planejamento.
B9: 4.0 | C9: PLANEJAMENTO | E9: Determine quais atividades são essenciais para aproveitar oportunidades ou evitar ameaças.
B11: 5.0 | C11: GRÁFICO PEST | E11: Visualize os dados consolidados através de gráficos.
B13: 6.0 | C13: ANÁLISE DO PLANEJAMENTO | E13: Analise graficamente o planejamento estruturado a partir da análise.
B15: 7.0 | C15: RESUMO | E15: Navegue pelas informações geradas a partir do cruzamento dos dados da análise.

Sheet Setores
B3: Cadastramento dos Setores da Empresa
B4: Financeiro
B5: Operações
B6: Qualidade
B7: Atendimento
B8: Segurança

Sheet Líderes
C2: areas
B3: Líderes | C3: Setor
B4: Colaborador 1 | C4: Financeiro
B5: Colaborador 2 | C5: Operações
B6: Colaborador 3 | C6: Operações
B7: Colaborador 4 | C7: Qualidade
B8: Colaborador 5 | C8: Atendimento
B9: Colaborador 6 | C9: Segurança

Sheet Fator Político
A4: =A2:A4 -> 0 | B4: Fator Analisado | C4: Importância | D4: Intensidade | E4: Tendência | F4: Pontuação | T4: 1 | U4: 1 | V4: 2 | W4: 2 | X4: 2 | Y4: 2
B5: Avanço da regulamentação da Inteligência Artificial no Brasil | C5: Totalmente importante | D5: Muito forte | E5: Piora muito | F5: =IF(ISERROR(VLOOKUP(C5,$H$7:$I$11,2,FALSE)*VLOOKUP(D5,$H$15:$I$19,2,FALSE)*VLOOKUP(E5,$H$23:$I$27,2,FALSE)),"",VLOOKUP(C5,$H$7:$I$11,2,FALSE)*VLOOKUP(D5,$H$15:$I$19,2,FALSE)*VLOOKUP(E5,$H$23:$I$27,2,FALSE)) -> 125 | H5: Importância | K5: 0.0002 | L5: =IF(F5="","",F5+K5) -> 125.0002 | M5: =IF(B5=0,"",B5) -> Avanço da regulamentação da Inteligência Artificial no Brasil | N5: =F5 -> 125
B6: Regulamentação e fiscalização da LGPD no uso de dados corporativos | C6: Totalmente importante | D6: Muito forte | E6: Mantém | F6: =IF(ISERROR(VLOOKUP(C6,$H$7:$I$11,2,FALSE)*VLOOKUP(D6,$H$15:$I$19,2,FALSE)*VLOOKUP(E6,$H$23:$I$27,2,FALSE)),"",VLOOKUP(C6,$H$7:$I$11,2,FALSE)*VLOOKUP(D6,$H$15:$I$19,2,FALSE)*VLOOKUP(E6,$H$23:$I$27,2,FALSE)) -> 75 | K6: 0.00019 | L6: =IF(F6="","",F6+K6) -> 75.00019 | M6: =IF(B6=0,"",B6) -> Regulamentação e fiscalização da LGPD no uso de dados corporativos | N6: =F6 -> 75
B7: Marcos regulatórios e de compliance no setor financeiro | C7: Importante | D7: Forte | E7: Melhora | F7: =IF(ISERROR(VLOOKUP(C7,$H$7:$I$11,2,FALSE)*VLOOKUP(D7,$H$15:$I$19,2,FALSE)*VLOOKUP(E7,$H$23:$I$27,2,FALSE)),"",VLOOKUP(C7,$H$7:$I$11,2,FALSE)*VLOOKUP(D7,$H$15:$I$19,2,FALSE)*VLOOKUP(E7,$H$23:$I$27,2,FALSE)) -> 24 | H7: Sem importância | I7: 1 | K7: 0.00018 | L7: =IF(F7="","",F7+K7) -> 24.00018 | M7: =IF(B7=0,"",B7) -> Marcos regulatórios e de compliance no setor financeiro | N7: =F7 -> 24
B8: Tributação sobre serviços de tecnologia e computação em nuvem | C8: Importante | D8: Forte | E8: Piora | F8: =IF(ISERROR(VLOOKUP(C8,$H$7:$I$11,2,FALSE)*VLOOKUP(D8,$H$15:$I$19,2,FALSE)*VLOOKUP(E8,$H$23:$I$27,2,FALSE)),"",VLOOKUP(C8,$H$7:$I$11,2,FALSE)*VLOOKUP(D8,$H$15:$I$19,2,FALSE)*VLOOKUP(E8,$H$23:$I$27,2,FALSE)) -> 48 | H8: Pouco importante | I8: 2 | K8: 0.00017 | L8: =IF(F8="","",F8+K8) -> 48.00017 | M8: =IF(B8=0,"",B8) -> Tributação sobre serviços de tecnologia e computação em nuvem | N8: =F8 -> 48
B9: Regras sobre transferência internacional de dados (Cloud) | C9: Importante | D9: Média | E9: Piora muito | F9: =IF(ISERROR(VLOOKUP(C9,$H$7:$I$11,2,FALSE)*VLOOKUP(D9,$H$15:$I$19,2,FALSE)*VLOOKUP(E9,$H$23:$I$27,2,FALSE)),"",VLOOKUP(C9,$H$7:$I$11,2,FALSE)*VLOOKUP(D9,$H$15:$I$19,2,FALSE)*VLOOKUP(E9,$H$23:$I$27,2,FALSE)) -> 45 | H9: Importante | I9: 3 | K9: 0.00016 | L9: =IF(F9="","",F9+K9) -> 45.00016 | M9: =IF(B9=0,"",B9) -> Regras sobre transferência internacional de dados (Cloud) | N9: =F9 -> 45
B10: Políticas de incentivo governamental à inovação e IA | C10: Importante | D10: Média | E10: Melhora | F10: =IF(ISERROR(VLOOKUP(C10,$H$7:$I$11,2,FALSE)*VLOOKUP(D10,$H$15:$I$19,2,FALSE)*VLOOKUP(E10,$H$23:$I$27,2,FALSE)),"",VLOOKUP(C10,$H$7:$I$11,2,FALSE)*VLOOKUP(D10,$H$15:$I$19,2,FALSE)*VLOOKUP(E10,$H$23:$I$27,2,FALSE)) -> 18 | H10: Muito importante | I10: 4 | K10: 0.00015 | L10: =IF(F10="","",F10+K10) -> 18.00015 | M10: =IF(B10=0,"",B10) -> Políticas de incentivo governamental à inovação e IA | N10: =F10 -> 18
B11: Leis trabalhistas e regulamentação de profissionais de TI (CLT vs. PJ) | C11: Sem importância | D11: Média | E11: Mantém | F11: =IF(ISERROR(VLOOKUP(C11,$H$7:$I$11,2,FALSE)*VLOOKUP(D11,$H$15:$I$19,2,FALSE)*VLOOKUP(E11,$H$23:$I$27,2,FALSE)),"",VLOOKUP(C11,$H$7:$I$11,2,FALSE)*VLOOKUP(D11,$H$15:$I$19,2,FALSE)*VLOOKUP(E11,$H$23:$I$27,2,FALSE)) -> 9 | H11: Totalmente importante | I11: 5 | K11: 0.00014 | L11: =IF(F11="","",F11+K11) -> 9.00014 | M11: =IF(B11=0,"",B11) -> Leis trabalhistas e regulamentação de profissionais de TI (CLT vs. PJ) | N11: =F11 -> 9
B12: Direitos autorais e Propriedade Intelectual em conteúdos gerados por IA | C12: Sem importância | D12: Fraca | E12: Piora | F12: =IF(ISERROR(VLOOKUP(C12,$H$7:$I$11,2,FALSE)*VLOOKUP(D12,$H$15:$I$19,2,FALSE)*VLOOKUP(E12,$H$23:$I$27,2,FALSE)),"",VLOOKUP(C12,$H$7:$I$11,2,FALSE)*VLOOKUP(D12,$H$15:$I$19,2,FALSE)*VLOOKUP(E12,$H$23:$I$27,2,FALSE)) -> 8 | K12: 0.00013 | L12: =IF(F12="","",F12+K12) -> 8.00013 | M12: =IF(B12=0,"",B12) -> Direitos autorais e Propriedade Intelectual em conteúdos gerados por IA | N12: =F12 -> 8
B13: Políticas governamentais de compras de TI e licitações | C13: Pouco importante | D13: Fraca | E13: Mantém | F13: =IF(ISERROR(VLOOKUP(C13,$H$7:$I$11,2,FALSE)*VLOOKUP(D13,$H$15:$I$19,2,FALSE)*VLOOKUP(E13,$H$23:$I$27,2,FALSE)),"",VLOOKUP(C13,$H$7:$I$11,2,FALSE)*VLOOKUP(D13,$H$15:$I$19,2,FALSE)*VLOOKUP(E13,$H$23:$I$27,2,FALSE)) -> 12 | H13: Intensidade | K13: 0.00012 | L13: =IF(F13="","",F13+K13) -> 12.00012 | M13: =IF(B13=0,"",B13) -> Políticas governamentais de compras de TI e licitações | N13: =F13 -> 12
B14: Regulamentação de soberania de dados nacionais | C14: Pouco importante | D14: Muito fraca | E14: Mantém | F14: =IF(ISERROR(VLOOKUP(C14,$H$7:$I$11,2,FALSE)*VLOOKUP(D14,$H$15:$I$19,2,FALSE)*VLOOKUP(E14,$H$23:$I$27,2,FALSE)),"",VLOOKUP(C14,$H$7:$I$11,2,FALSE)*VLOOKUP(D14,$H$15:$I$19,2,FALSE)*VLOOKUP(E14,$H$23:$I$27,2,FALSE)) -> 6 | K14: 0.00011 | L14: =IF(F14="","",F14+K14) -> 6.00011 | M14: =IF(B14=0,"",B14) -> Regulamentação de soberania de dados nacionais | N14: =F14 -> 6
F15: =IF(ISERROR(VLOOKUP(C15,$H$7:$I$11,2,FALSE)*VLOOKUP(D15,$H$15:$I$19,2,FALSE)*VLOOKUP(E15,$H$23:$I$27,2,FALSE)),"",VLOOKUP(C15,$H$7:$I$11,2,FALSE)*VLOOKUP(D15,$H$15:$I$19,2,FALSE)*VLOOKUP(E15,$H$23:$I$27,2,FALSE)) | H15: Muito forte | I15: 5 | K15: 0.0001 | L15: =IF(F15="","",F15+K15) | M15: =IF(B15=0,"",B15) | N15: =F15
F16: =IF(ISERROR(VLOOKUP(C16,$H$7:$I$11,2,FALSE)*VLOOKUP(D16,$H$15:$I$19,2,FALSE)*VLOOKUP(E16,$H$23:$I$27,2,FALSE)),"",VLOOKUP(C16,$H$7:$I$11,2,FALSE)*VLOOKUP(D16,$H$15:$I$19,2,FALSE)*VLOOKUP(E16,$H$23:$I$27,2,FALSE)) | H16: Forte | I16: 4 | K16: 9e-05 | L16: =IF(F16="","",F16+K16) | M16: =IF(B16=0,"",B16) | N16: =F16
F17: =IF(ISERROR(VLOOKUP(C17,$H$7:$I$11,2,FALSE)*VLOOKUP(D17,$H$15:$I$19,2,FALSE)*VLOOKUP(E17,$H$23:$I$27,2,FALSE)),"",VLOOKUP(C17,$H$7:$I$11,2,FALSE)*VLOOKUP(D17,$H$15:$I$19,2,FALSE)*VLOOKUP(E17,$H$23:$I$27,2,FALSE)) | H17: Média | I17: 3 | K17: 8e-05 | L17: =IF(F17="","",F17+K17) | M17: =IF(B17=0,"",B17) | N17: =F17
F18: =IF(ISERROR(VLOOKUP(C18,$H$7:$I$11,2,FALSE)*VLOOKUP(D18,$H$15:$I$19,2,FALSE)*VLOOKUP(E18,$H$23:$I$27,2,FALSE)),"",VLOOKUP(C18,$H$7:$I$11,2,FALSE)*VLOOKUP(D18,$H$15:$I$19,2,FALSE)*VLOOKUP(E18,$H$23:$I$27,2,FALSE)) | H18: Fraca | I18: 2 | K18: 7e-05 | L18: =IF(F18="","",F18+K18) | M18: =IF(B18=0,"",B18) | N18: =F18
F19: =IF(ISERROR(VLOOKUP(C19,$H$7:$I$11,2,FALSE)*VLOOKUP(D19,$H$15:$I$19,2,FALSE)*VLOOKUP(E19,$H$23:$I$27,2,FALSE)),"",VLOOKUP(C19,$H$7:$I$11,2,FALSE)*VLOOKUP(D19,$H$15:$I$19,2,FALSE)*VLOOKUP(E19,$H$23:$I$27,2,FALSE)) | H19: Muito fraca | I19: 1 | K19: 6e-05 | L19: =IF(F19="","",F19+K19) | M19: =IF(B19=0,"",B19) | N19: =F19
F20: =IF(ISERROR(VLOOKUP(C20,$H$7:$I$11,2,FALSE)*VLOOKUP(D20,$H$15:$I$19,2,FALSE)*VLOOKUP(E20,$H$23:$I$27,2,FALSE)),"",VLOOKUP(C20,$H$7:$I$11,2,FALSE)*VLOOKUP(D20,$H$15:$I$19,2,FALSE)*VLOOKUP(E20,$H$23:$I$27,2,FALSE)) | K20: 5e-05 | L20: =IF(F20="","",F20+K20) | M20: =IF(B20=0,"",B20) | N20: =F20
F21: =IF(ISERROR(VLOOKUP(C21,$H$7:$I$11,2,FALSE)*VLOOKUP(D21,$H$15:$I$19,2,FALSE)*VLOOKUP(E21,$H$23:$I$27,2,FALSE)),"",VLOOKUP(C21,$H$7:$I$11,2,FALSE)*VLOOKUP(D21,$H$15:$I$19,2,FALSE)*VLOOKUP(E21,$H$23:$I$27,2,FALSE)) | H21: Tendência | K21: 4e-05 | L21: =IF(F21="","",F21+K21) | M21: =IF(B21=0,"",B21) | N21: =F21
F22: =IF(ISERROR(VLOOKUP(C22,$H$7:$I$11,2,FALSE)*VLOOKUP(D22,$H$15:$I$19,2,FALSE)*VLOOKUP(E22,$H$23:$I$27,2,FALSE)),"",VLOOKUP(C22,$H$7:$I$11,2,FALSE)*VLOOKUP(D22,$H$15:$I$19,2,FALSE)*VLOOKUP(E22,$H$23:$I$27,2,FALSE)) | K22: 3e-05 | L22: =IF(F22="","",F22+K22) | M22: =IF(B22=0,"",B22) | N22: =F22
F23: =IF(ISERROR(VLOOKUP(C23,$H$7:$I$11,2,FALSE)*VLOOKUP(D23,$H$15:$I$19,2,FALSE)*VLOOKUP(E23,$H$23:$I$27,2,FALSE)),"",VLOOKUP(C23,$H$7:$I$11,2,FALSE)*VLOOKUP(D23,$H$15:$I$19,2,FALSE)*VLOOKUP(E23,$H$23:$I$27,2,FALSE)) | H23: Melhora muito | I23: 1 | K23: 2e-05 | L23: =IF(F23="","",F23+K23) | M23: =IF(B23=0,"",B23) | N23: =F23
F24: =IF(ISERROR(VLOOKUP(C24,$H$7:$I$11,2,FALSE)*VLOOKUP(D24,$H$15:$I$19,2,FALSE)*VLOOKUP(E24,$H$23:$I$27,2,FALSE)),"",VLOOKUP(C24,$H$7:$I$11,2,FALSE)*VLOOKUP(D24,$H$15:$I$19,2,FALSE)*VLOOKUP(E24,$H$23:$I$27,2,FALSE)) | H24: Melhora | I24: 2 | K24: 1e-05 | L24: =IF(F24="","",F24+K24) | M24: =IF(B24=0,"",B24) | N24: =F24
B25: Pontuação geral dos fatores políticos | E25: → | F25: =SUM(F5:F24) -> 370 | H25: Mantém | I25: 3
H26: Piora | I26: 4
H27: Piora muito | I27: 5

Sheet Fator Econômico
B3: Fator Analisado | C3: Importância | D3: Intensidade | E3: Tendência | F3: Pontuação
B4: Variação cambial (Dólar) impactando licenças de Cloud (AWS, Azure, etc.) | C4: Totalmente importante | D4: Muito forte | E4: Piora | F4: =IF(ISERROR(VLOOKUP(C4,$H$6:$I$10,2,FALSE)*VLOOKUP(D4,$H$14:$I$18,2,FALSE)*VLOOKUP(E4,$H$22:$I$26,2,FALSE)),"",VLOOKUP(C4,$H$6:$I$10,2,FALSE)*VLOOKUP(D4,$H$14:$I$18,2,FALSE)*VLOOKUP(E4,$H$22:$I$26,2,FALSE)) -> 100 | H4: Importância | K4: 0.0002 | L4: =IF(F4="","",F4+K4) -> 100.0002 | M4: =IF(B4=0,"",B4) -> Variação cambial (Dólar) impactando licenças de Cloud (AWS, Azure, etc.) | N4: =F4 -> 100
B5: Crescimento de investimentos tecnológicos no Setor Financeiro e Seguradoras | C5: Totalmente importante | D5: Forte | E5: Melhora muito | F5: =IF(ISERROR(VLOOKUP(C5,$H$6:$I$10,2,FALSE)*VLOOKUP(D5,$H$14:$I$18,2,FALSE)*VLOOKUP(E5,$H$22:$I$26,2,FALSE)),"",VLOOKUP(C5,$H$6:$I$10,2,FALSE)*VLOOKUP(D5,$H$14:$I$18,2,FALSE)*VLOOKUP(E5,$H$22:$I$26,2,FALSE)) -> 20 | K5: 0.00019 | L5: =IF(F5="","",F5+K5) -> 20.00019 | M5: =IF(B5=0,"",B5) -> Crescimento de investimentos tecnológicos no Setor Financeiro e Seguradoras | N5: =F5 -> 20
B6: Inflação salarial e custo para atração/retenção de talentos de TI | C6: Importante | D6: Forte | E6: Piora | F6: =IF(ISERROR(VLOOKUP(C6,$H$6:$I$10,2,FALSE)*VLOOKUP(D6,$H$14:$I$18,2,FALSE)*VLOOKUP(E6,$H$22:$I$26,2,FALSE)),"",VLOOKUP(C6,$H$6:$I$10,2,FALSE)*VLOOKUP(D6,$H$14:$I$18,2,FALSE)*VLOOKUP(E6,$H$22:$I$26,2,FALSE)) -> 48 | H6: Sem importância | I6: 1 | K6: 0.00018 | L6: =IF(F6="","",F6+K6) -> 48.00018 | M6: =IF(B6=0,"",B6) -> Inflação salarial e custo para atração/retenção de talentos de TI | N6: =F6 -> 48
B7: Orçamento corporativo focado em eficiência e redução de custos (FinOps) | C7: Importante | D7: Forte | E7: Melhora muito | F7: =IF(ISERROR(VLOOKUP(C7,$H$6:$I$10,2,FALSE)*VLOOKUP(D7,$H$14:$I$18,2,FALSE)*VLOOKUP(E7,$H$22:$I$26,2,FALSE)),"",VLOOKUP(C7,$H$6:$I$10,2,FALSE)*VLOOKUP(D7,$H$14:$I$18,2,FALSE)*VLOOKUP(E7,$H$22:$I$26,2,FALSE)) -> 12 | H7: Pouco importante | I7: 2 | K7: 0.00017 | L7: =IF(F7="","",F7+K7) -> 12.00017 | M7: =IF(B7=0,"",B7) -> Orçamento corporativo focado em eficiência e redução de custos (FinOps) | N7: =F7 -> 12
B8: Competitividade e pressão sobre o pricing de consultorias de dados | C8: Importante | D8: Média | E8: Piora | F8: =IF(ISERROR(VLOOKUP(C8,$H$6:$I$10,2,FALSE)*VLOOKUP(D8,$H$14:$I$18,2,FALSE)*VLOOKUP(E8,$H$22:$I$26,2,FALSE)),"",VLOOKUP(C8,$H$6:$I$10,2,FALSE)*VLOOKUP(D8,$H$14:$I$18,2,FALSE)*VLOOKUP(E8,$H$22:$I$26,2,FALSE)) -> 36 | H8: Importante | I8: 3 | K8: 0.00016 | L8: =IF(F8="","",F8+K8) -> 36.00016 | M8: =IF(B8=0,"",B8) -> Competitividade e pressão sobre o pricing de consultorias de dados | N8: =F8 -> 36
B9: Taxa de juros (Selic) afetando o crédito para expansão de clientes B2B | C9: Sem importância | D9: Média | E9: Mantém | F9: =IF(ISERROR(VLOOKUP(C9,$H$6:$I$10,2,FALSE)*VLOOKUP(D9,$H$14:$I$18,2,FALSE)*VLOOKUP(E9,$H$22:$I$26,2,FALSE)),"",VLOOKUP(C9,$H$6:$I$10,2,FALSE)*VLOOKUP(D9,$H$14:$I$18,2,FALSE)*VLOOKUP(E9,$H$22:$I$26,2,FALSE)) -> 9 | H9: Muito importante | I9: 4 | K9: 0.00015 | L9: =IF(F9="","",F9+K9) -> 9.00015 | M9: =IF(B9=0,"",B9) -> Taxa de juros (Selic) afetando o crédito para expansão de clientes B2B | N9: =F9 -> 9
B10: Custos de infraestrutura para expansão da equipe interna em 40% | C10: Sem importância | D10: Média | E10: Piora | F10: =IF(ISERROR(VLOOKUP(C10,$H$6:$I$10,2,FALSE)*VLOOKUP(D10,$H$14:$I$18,2,FALSE)*VLOOKUP(E10,$H$22:$I$26,2,FALSE)),"",VLOOKUP(C10,$H$6:$I$10,2,FALSE)*VLOOKUP(D10,$H$14:$I$18,2,FALSE)*VLOOKUP(E10,$H$22:$I$26,2,FALSE)) -> 12 | H10: Totalmente importante | I10: 5 | K10: 0.00014 | L10: =IF(F10="","",F10+K10) -> 12.00014 | M10: =IF(B10=0,"",B10) -> Custos de infraestrutura para expansão da equipe interna em 40% | N10: =F10 -> 12
B11: Acesso a capital de risco e investimentos no ecossistema de tecnologia | C11: Pouco importante | D11: Fraca | E11: Mantém | F11: =IF(ISERROR(VLOOKUP(C11,$H$6:$I$10,2,FALSE)*VLOOKUP(D11,$H$14:$I$18,2,FALSE)*VLOOKUP(E11,$H$22:$I$26,2,FALSE)),"",VLOOKUP(C11,$H$6:$I$10,2,FALSE)*VLOOKUP(D11,$H$14:$I$18,2,FALSE)*VLOOKUP(E11,$H$22:$I$26,2,FALSE)) -> 12 | K11: 0.00013 | L11: =IF(F11="","",F11+K11) -> 12.00013 | M11: =IF(B11=0,"",B11) -> Acesso a capital de risco e investimentos no ecossistema de tecnologia | N11: =F11 -> 12
B12: Risco de instabilidade econômica global afetando renovações de contratos | C12: Pouco importante | D12: Fraca | E12: Mantém | F12: =IF(ISERROR(VLOOKUP(C12,$H$6:$I$10,2,FALSE)*VLOOKUP(D12,$H$14:$I$18,2,FALSE)*VLOOKUP(E12,$H$22:$I$26,2,FALSE)),"",VLOOKUP(C12,$H$6:$I$10,2,FALSE)*VLOOKUP(D12,$H$14:$I$18,2,FALSE)*VLOOKUP(E12,$H$22:$I$26,2,FALSE)) -> 12 | H12: Intensidade | K12: 0.00012 | L12: =IF(F12="","",F12+K12) -> 12.00012 | M12: =IF(B12=0,"",B12) -> Risco de instabilidade econômica global afetando renovações de contratos | N12: =F12 -> 12
B13: Inflação geral impactando os custos operacionais da QSOFT | C13: Pouco importante | D13: Muito fraca | E13: Mantém | F13: =IF(ISERROR(VLOOKUP(C13,$H$6:$I$10,2,FALSE)*VLOOKUP(D13,$H$14:$I$18,2,FALSE)*VLOOKUP(E13,$H$22:$I$26,2,FALSE)),"",VLOOKUP(C13,$H$6:$I$10,2,FALSE)*VLOOKUP(D13,$H$14:$I$18,2,FALSE)*VLOOKUP(E13,$H$22:$I$26,2,FALSE)) -> 6 | K13: 0.00011 | L13: =IF(F13="","",F13+K13) -> 6.00011 | M13: =IF(B13=0,"",B13) -> Inflação geral impactando os custos operacionais da QSOFT | N13: =F13 -> 6
F14: =IF(ISERROR(VLOOKUP(C14,$H$6:$I$10,2,FALSE)*VLOOKUP(D14,$H$14:$I$18,2,FALSE)*VLOOKUP(E14,$H$22:$I$26,2,FALSE)),"",VLOOKUP(C14,$H$6:$I$10,2,FALSE)*VLOOKUP(D14,$H$14:$I$18,2,FALSE)*VLOOKUP(E14,$H$22:$I$26,2,FALSE)) | H14: Muito forte | I14: 5 | K14: 0.0001 | L14: =IF(F14="","",F14+K14) | M14: =IF(B14=0,"",B14) | N14: =F14
F15: =IF(ISERROR(VLOOKUP(C15,$H$6:$I$10,2,FALSE)*VLOOKUP(D15,$H$14:$I$18,2,FALSE)*VLOOKUP(E15,$H$22:$I$26,2,FALSE)),"",VLOOKUP(C15,$H$6:$I$10,2,FALSE)*VLOOKUP(D15,$H$14:$I$18,2,FALSE)*VLOOKUP(E15,$H$22:$I$26,2,FALSE)) | H15: Forte | I15: 4 | K15: 9e-05 | L15: =IF(F15="","",F15+K15) | M15: =IF(B15=0,"",B15) | N15: =F15
F16: =IF(ISERROR(VLOOKUP(C16,$H$6:$I$10,2,FALSE)*VLOOKUP(D16,$H$14:$I$18,2,FALSE)*VLOOKUP(E16,$H$22:$I$26,2,FALSE)),"",VLOOKUP(C16,$H$6:$I$10,2,FALSE)*VLOOKUP(D16,$H$14:$I$18,2,FALSE)*VLOOKUP(E16,$H$22:$I$26,2,FALSE)) | H16: Média | I16: 3 | K16: 8e-05 | L16: =IF(F16="","",F16+K16) | M16: =IF(B16=0,"",B16) | N16: =F16
F17: =IF(ISERROR(VLOOKUP(C17,$H$6:$I$10,2,FALSE)*VLOOKUP(D17,$H$14:$I$18,2,FALSE)*VLOOKUP(E17,$H$22:$I$26,2,FALSE)),"",VLOOKUP(C17,$H$6:$I$10,2,FALSE)*VLOOKUP(D17,$H$14:$I$18,2,FALSE)*VLOOKUP(E17,$H$22:$I$26,2,FALSE)) | H17: Fraca | I17: 2 | K17: 7e-05 | L17: =IF(F17="","",F17+K17) | M17: =IF(B17=0,"",B17) | N17: =F17
F18: =IF(ISERROR(VLOOKUP(C18,$H$6:$I$10,2,FALSE)*VLOOKUP(D18,$H$14:$I$18,2,FALSE)*VLOOKUP(E18,$H$22:$I$26,2,FALSE)),"",VLOOKUP(C18,$H$6:$I$10,2,FALSE)*VLOOKUP(D18,$H$14:$I$18,2,FALSE)*VLOOKUP(E18,$H$22:$I$26,2,FALSE)) | H18: Muito fraca | I18: 1 | K18: 6e-05 | L18: =IF(F18="","",F18+K18) | M18: =IF(B18=0,"",B18) | N18: =F18
F19: =IF(ISERROR(VLOOKUP(C19,$H$6:$I$10,2,FALSE)*VLOOKUP(D19,$H$14:$I$18,2,FALSE)*VLOOKUP(E19,$H$22:$I$26,2,FALSE)),"",VLOOKUP(C19,$H$6:$I$10,2,FALSE)*VLOOKUP(D19,$H$14:$I$18,2,FALSE)*VLOOKUP(E19,$H$22:$I$26,2,FALSE)) | K19: 5e-05 | L19: =IF(F19="","",F19+K19) | M19: =IF(B19=0,"",B19) | N19: =F19
F20: =IF(ISERROR(VLOOKUP(C20,$H$6:$I$10,2,FALSE)*VLOOKUP(D20,$H$14:$I$18,2,FALSE)*VLOOKUP(E20,$H$22:$I$26,2,FALSE)),"",VLOOKUP(C20,$H$6:$I$10,2,FALSE)*VLOOKUP(D20,$H$14:$I$18,2,FALSE)*VLOOKUP(E20,$H$22:$I$26,2,FALSE)) | H20: Tendência | K20: 4e-05 | L20: =IF(F20="","",F20+K20) | M20: =IF(B20=0,"",B20) | N20: =F20
F21: =IF(ISERROR(VLOOKUP(C21,$H$6:$I$10,2,FALSE)*VLOOKUP(D21,$H$14:$I$18,2,FALSE)*VLOOKUP(E21,$H$22:$I$26,2,FALSE)),"",VLOOKUP(C21,$H$6:$I$10,2,FALSE)*VLOOKUP(D21,$H$14:$I$18,2,FALSE)*VLOOKUP(E21,$H$22:$I$26,2,FALSE)) | K21: 3e-05 | L21: =IF(F21="","",F21+K21) | M21: =IF(B21=0,"",B21) | N21: =F21
F22: =IF(ISERROR(VLOOKUP(C22,$H$6:$I$10,2,FALSE)*VLOOKUP(D22,$H$14:$I$18,2,FALSE)*VLOOKUP(E22,$H$22:$I$26,2,FALSE)),"",VLOOKUP(C22,$H$6:$I$10,2,FALSE)*VLOOKUP(D22,$H$14:$I$18,2,FALSE)*VLOOKUP(E22,$H$22:$I$26,2,FALSE)) | H22: Melhora muito | I22: 1 | K22: 2e-05 | L22: =IF(F22="","",F22+K22) | M22: =IF(B22=0,"",B22) | N22: =F22
F23: =IF(ISERROR(VLOOKUP(C23,$H$6:$I$10,2,FALSE)*VLOOKUP(D23,$H$14:$I$18,2,FALSE)*VLOOKUP(E23,$H$22:$I$26,2,FALSE)),"",VLOOKUP(C23,$H$6:$I$10,2,FALSE)*VLOOKUP(D23,$H$14:$I$18,2,FALSE)*VLOOKUP(E23,$H$22:$I$26,2,FALSE)) | H23: Melhora | I23: 2 | K23: 1e-05 | L23: =IF(F23="","",F23+K23) | M23: =IF(B23=0,"",B23) | N23: =F23
B24: Pontuação geral dos fatores econômicos | E24: → | F24: =SUM(F4:F23) -> 267 | H24: Mantém | I24: 3
H25: Piora | I25: 4
H26: Piora muito | I26: 5

Sheet Fator Social
B3: Fator Analisado | C3: Importância | D3: Intensidade | E3: Tendência | F3: Pontuação
B4: Adoção descontrolada de ferramentas de IA pelos funcionários (Shadow AI) | C4: Totalmente importante | D4: Muito forte | E4: Piora muito | F4: =IF(ISERROR(VLOOKUP(C4,$H$6:$I$10,2,FALSE)*VLOOKUP(D4,$H$14:$I$18,2,FALSE)*VLOOKUP(E4,$H$22:$I$26,2,FALSE)),"",VLOOKUP(C4,$H$6:$I$10,2,FALSE)*VLOOKUP(D4,$H$14:$I$18,2,FALSE)*VLOOKUP(E4,$H$22:$I$26,2,FALSE)) -> 125 | H4: Importância | K4: 0.0002 | L4: =IF(F4="","",F4+K4) -> 125.0002 | M4: =IF(B4=0,"",B4) -> Adoção descontrolada de ferramentas de IA pelos funcionários (Shadow AI) | N4: =F4 -> 125
B5: Escassez de mão de obra superespecializada em dados e IA no mercado | C5: Totalmente importante | D5: Forte | E5: Piora | F5: =IF(ISERROR(VLOOKUP(C5,$H$6:$I$10,2,FALSE)*VLOOKUP(D5,$H$14:$I$18,2,FALSE)*VLOOKUP(E5,$H$22:$I$26,2,FALSE)),"",VLOOKUP(C5,$H$6:$I$10,2,FALSE)*VLOOKUP(D5,$H$14:$I$18,2,FALSE)*VLOOKUP(E5,$H$22:$I$26,2,FALSE)) -> 80 | K5: 0.00019 | L5: =IF(F5="","",F5+K5) -> 80.00019 | M5: =IF(B5=0,"",B5) -> Escassez de mão de obra superespecializada em dados e IA no mercado | N5: =F5 -> 80
B6: Mudança de cultura corporativa focada em tomada de decisão baseada em dados | C6: Importante | D6: Forte | E6: Melhora muito | F6: =IF(ISERROR(VLOOKUP(C6,$H$6:$I$10,2,FALSE)*VLOOKUP(D6,$H$14:$I$18,2,FALSE)*VLOOKUP(E6,$H$22:$I$26,2,FALSE)),"",VLOOKUP(C6,$H$6:$I$10,2,FALSE)*VLOOKUP(D6,$H$14:$I$18,2,FALSE)*VLOOKUP(E6,$H$22:$I$26,2,FALSE)) -> 12 | H6: Sem importância | I6: 1 | K6: 0.00018 | L6: =IF(F6="","",F6+K6) -> 12.00018 | M6: =IF(B6=0,"",B6) -> Mudança de cultura corporativa focada em tomada de decisão baseada em dados | N6: =F6 -> 12
B7: Preocupação crescente com a privacidade e vazamento de dados corporativos | C7: Importante | D7: Forte | E7: Piora | F7: =IF(ISERROR(VLOOKUP(C7,$H$6:$I$10,2,FALSE)*VLOOKUP(D7,$H$14:$I$18,2,FALSE)*VLOOKUP(E7,$H$22:$I$26,2,FALSE)),"",VLOOKUP(C7,$H$6:$I$10,2,FALSE)*VLOOKUP(D7,$H$14:$I$18,2,FALSE)*VLOOKUP(E7,$H$22:$I$26,2,FALSE)) -> 48 | H7: Pouco importante | I7: 2 | K7: 0.00017 | L7: =IF(F7="","",F7+K7) -> 48.00017 | M7: =IF(B7=0,"",B7) -> Preocupação crescente com a privacidade e vazamento de dados corporativos | N7: =F7 -> 48
B8: Necessidade contínua de capacitação das equipes (Lifelong learning) | C8: Importante | D8: Média | E8: Melhora | F8: =IF(ISERROR(VLOOKUP(C8,$H$6:$I$10,2,FALSE)*VLOOKUP(D8,$H$14:$I$18,2,FALSE)*VLOOKUP(E8,$H$22:$I$26,2,FALSE)),"",VLOOKUP(C8,$H$6:$I$10,2,FALSE)*VLOOKUP(D8,$H$14:$I$18,2,FALSE)*VLOOKUP(E8,$H$22:$I$26,2,FALSE)) -> 18 | H8: Importante | I8: 3 | K8: 0.00016 | L8: =IF(F8="","",F8+K8) -> 18.00016 | M8: =IF(B8=0,"",B8) -> Necessidade contínua de capacitação das equipes (Lifelong learning) | N8: =F8 -> 18
B9: Maturidade digital e resistência à mudança por parte de stakeholders não-técnicos | C9: Sem importância | D9: Média | E9: Mantém | F9: =IF(ISERROR(VLOOKUP(C9,$H$6:$I$10,2,FALSE)*VLOOKUP(D9,$H$14:$I$18,2,FALSE)*VLOOKUP(E9,$H$22:$I$26,2,FALSE)),"",VLOOKUP(C9,$H$6:$I$10,2,FALSE)*VLOOKUP(D9,$H$14:$I$18,2,FALSE)*VLOOKUP(E9,$H$22:$I$26,2,FALSE)) -> 9 | H9: Muito importante | I9: 4 | K9: 0.00015 | L9: =IF(F9="","",F9+K9) -> 9.00015 | M9: =IF(B9=0,"",B9) -> Maturidade digital e resistência à mudança por parte de stakeholders não-técnicos | N9: =F9 -> 9
B10: Impacto do trabalho remoto/híbrido no aculturamento de novos colaboradores | C10: Sem importância | D10: Média | E10: Mantém | F10: =IF(ISERROR(VLOOKUP(C10,$H$6:$I$10,2,FALSE)*VLOOKUP(D10,$H$14:$I$18,2,FALSE)*VLOOKUP(E10,$H$22:$I$26,2,FALSE)),"",VLOOKUP(C10,$H$6:$I$10,2,FALSE)*VLOOKUP(D10,$H$14:$I$18,2,FALSE)*VLOOKUP(E10,$H$22:$I$26,2,FALSE)) -> 9 | H10: Totalmente importante | I10: 5 | K10: 0.00014 | L10: =IF(F10="","",F10+K10) -> 9.00014 | M10: =IF(B10=0,"",B10) -> Impacto do trabalho remoto/híbrido no aculturamento de novos colaboradores | N10: =F10 -> 9
B11: Expectativa do cliente por hiperpersonalização e atendimento consultivo próximo | C11: Sem importância | D11: Média | E11: Melhora | F11: =IF(ISERROR(VLOOKUP(C11,$H$6:$I$10,2,FALSE)*VLOOKUP(D11,$H$14:$I$18,2,FALSE)*VLOOKUP(E11,$H$22:$I$26,2,FALSE)),"",VLOOKUP(C11,$H$6:$I$10,2,FALSE)*VLOOKUP(D11,$H$14:$I$18,2,FALSE)*VLOOKUP(E11,$H$22:$I$26,2,FALSE)) -> 6 | K11: 0.00013 | L11: =IF(F11="","",F11+K11) -> 6.00013 | M11: =IF(B11=0,"",B11) -> Expectativa do cliente por hiperpersonalização e atendimento consultivo próximo | N11: =F11 -> 6
B12: Resistência social e medo da substituição de empregos por Inteligência Artificial | C12: Pouco importante | D12: Fraca | E12: Piora | F12: =IF(ISERROR(VLOOKUP(C12,$H$6:$I$10,2,FALSE)*VLOOKUP(D12,$H$14:$I$18,2,FALSE)*VLOOKUP(E12,$H$22:$I$26,2,FALSE)),"",VLOOKUP(C12,$H$6:$I$10,2,FALSE)*VLOOKUP(D12,$H$14:$I$18,2,FALSE)*VLOOKUP(E12,$H$22:$I$26,2,FALSE)) -> 16 | H12: Intensidade | K12: 0.00012 | L12: =IF(F12="","",F12+K12) -> 16.00012 | M12: =IF(B12=0,"",B12) -> Resistência social e medo da substituição de empregos por Inteligência Artificial | N12: =F12 -> 16
B13: Síndrome de burnout e esgotamento mental em profissionais de tecnologia | C13: Pouco importante | D13: Muito fraca | E13: Mantém | F13: =IF(ISERROR(VLOOKUP(C13,$H$6:$I$10,2,FALSE)*VLOOKUP(D13,$H$14:$I$18,2,FALSE)*VLOOKUP(E13,$H$22:$I$26,2,FALSE)),"",VLOOKUP(C13,$H$6:$I$10,2,FALSE)*VLOOKUP(D13,$H$14:$I$18,2,FALSE)*VLOOKUP(E13,$H$22:$I$26,2,FALSE)) -> 6 | K13: 0.00011 | L13: =IF(F13="","",F13+K13) -> 6.00011 | M13: =IF(B13=0,"",B13) -> Síndrome de burnout e esgotamento mental em profissionais de tecnologia | N13: =F13 -> 6
F14: =IF(ISERROR(VLOOKUP(C14,$H$6:$I$10,2,FALSE)*VLOOKUP(D14,$H$14:$I$18,2,FALSE)*VLOOKUP(E14,$H$22:$I$26,2,FALSE)),"",VLOOKUP(C14,$H$6:$I$10,2,FALSE)*VLOOKUP(D14,$H$14:$I$18,2,FALSE)*VLOOKUP(E14,$H$22:$I$26,2,FALSE)) | H14: Muito forte | I14: 5 | K14: 0.0001 | L14: =IF(F14="","",F14+K14) | M14: =IF(B14=0,"",B14) | N14: =F14
F15: =IF(ISERROR(VLOOKUP(C15,$H$6:$I$10,2,FALSE)*VLOOKUP(D15,$H$14:$I$18,2,FALSE)*VLOOKUP(E15,$H$22:$I$26,2,FALSE)),"",VLOOKUP(C15,$H$6:$I$10,2,FALSE)*VLOOKUP(D15,$H$14:$I$18,2,FALSE)*VLOOKUP(E15,$H$22:$I$26,2,FALSE)) | H15: Forte | I15: 4 | K15: 9e-05 | L15: =IF(F15="","",F15+K15) | M15: =IF(B15=0,"",B15) | N15: =F15
F16: =IF(ISERROR(VLOOKUP(C16,$H$6:$I$10,2,FALSE)*VLOOKUP(D16,$H$14:$I$18,2,FALSE)*VLOOKUP(E16,$H$22:$I$26,2,FALSE)),"",VLOOKUP(C16,$H$6:$I$10,2,FALSE)*VLOOKUP(D16,$H$14:$I$18,2,FALSE)*VLOOKUP(E16,$H$22:$I$26,2,FALSE)) | H16: Média | I16: 3 | K16: 8e-05 | L16: =IF(F16="","",F16+K16) | M16: =IF(B16=0,"",B16) | N16: =F16
F17: =IF(ISERROR(VLOOKUP(C17,$H$6:$I$10,2,FALSE)*VLOOKUP(D17,$H$14:$I$18,2,FALSE)*VLOOKUP(E17,$H$22:$I$26,2,FALSE)),"",VLOOKUP(C17,$H$6:$I$10,2,FALSE)*VLOOKUP(D17,$H$14:$I$18,2,FALSE)*VLOOKUP(E17,$H$22:$I$26,2,FALSE)) | H17: Fraca | I17: 2 | K17: 7e-05 | L17: =IF(F17="","",F17+K17) | M17: =IF(B17=0,"",B17) | N17: =F17
F18: =IF(ISERROR(VLOOKUP(C18,$H$6:$I$10,2,FALSE)*VLOOKUP(D18,$H$14:$I$18,2,FALSE)*VLOOKUP(E18,$H$22:$I$26,2,FALSE)),"",VLOOKUP(C18,$H$6:$I$10,2,FALSE)*VLOOKUP(D18,$H$14:$I$18,2,FALSE)*VLOOKUP(E18,$H$22:$I$26,2,FALSE)) | H18: Muito fraca | I18: 1 | K18: 6e-05 | L18: =IF(F18="","",F18+K18) | M18: =IF(B18=0,"",B18) | N18: =F18
F19: =IF(ISERROR(VLOOKUP(C19,$H$6:$I$10,2,FALSE)*VLOOKUP(D19,$H$14:$I$18,2,FALSE)*VLOOKUP(E19,$H$22:$I$26,2,FALSE)),"",VLOOKUP(C19,$H$6:$I$10,2,FALSE)*VLOOKUP(D19,$H$14:$I$18,2,FALSE)*VLOOKUP(E19,$H$22:$I$26,2,FALSE)) | K19: 5e-05 | L19: =IF(F19="","",F19+K19) | M19: =IF(B19=0,"",B19) | N19: =F19
F20: =IF(ISERROR(VLOOKUP(C20,$H$6:$I$10,2,FALSE)*VLOOKUP(D20,$H$14:$I$18,2,FALSE)*VLOOKUP(E20,$H$22:$I$26,2,FALSE)),"",VLOOKUP(C20,$H$6:$I$10,2,FALSE)*VLOOKUP(D20,$H$14:$I$18,2,FALSE)*VLOOKUP(E20,$H$22:$I$26,2,FALSE)) | H20: Tendência | K20: 4e-05 | L20: =IF(F20="","",F20+K20) | M20: =IF(B20=0,"",B20) | N20: =F20
F21: =IF(ISERROR(VLOOKUP(C21,$H$6:$I$10,2,FALSE)*VLOOKUP(D21,$H$14:$I$18,2,FALSE)*VLOOKUP(E21,$H$22:$I$26,2,FALSE)),"",VLOOKUP(C21,$H$6:$I$10,2,FALSE)*VLOOKUP(D21,$H$14:$I$18,2,FALSE)*VLOOKUP(E21,$H$22:$I$26,2,FALSE)) | K21: 3e-05 | L21: =IF(F21="","",F21+K21) | M21: =IF(B21=0,"",B21) | N21: =F21
F22: =IF(ISERROR(VLOOKUP(C22,$H$6:$I$10,2,FALSE)*VLOOKUP(D22,$H$14:$I$18,2,FALSE)*VLOOKUP(E22,$H$22:$I$26,2,FALSE)),"",VLOOKUP(C22,$H$6:$I$10,2,FALSE)*VLOOKUP(D22,$H$14:$I$18,2,FALSE)*VLOOKUP(E22,$H$22:$I$26,2,FALSE)) | H22: Melhora muito | I22: 1 | K22: 2e-05 | L22: =IF(F22="","",F22+K22) | M22: =IF(B22=0,"",B22) | N22: =F22
F23: =IF(ISERROR(VLOOKUP(C23,$H$6:$I$10,2,FALSE)*VLOOKUP(D23,$H$14:$I$18,2,FALSE)*VLOOKUP(E23,$H$22:$I$26,2,FALSE)),"",VLOOKUP(C23,$H$6:$I$10,2,FALSE)*VLOOKUP(D23,$H$14:$I$18,2,FALSE)*VLOOKUP(E23,$H$22:$I$26,2,FALSE)) | H23: Melhora | I23: 2 | K23: 1e-05 | L23: =IF(F23="","",F23+K23) | M23: =IF(B23=0,"",B23) | N23: =F23
B24: Pontuação geral dos fatores sociais | E24: → | F24: =SUM(F4:F23) -> 329 | H24: Mantém | I24: 3
H25: Piora | I25: 4
H26: Piora muito | I26: 5

Sheet Fator Tecnológico
B3: Fator Analisado | C3: Importância | D3: Intensidade | E3: Tendência | F3: Pontuação
B4: Rápida evolução e surgimento de novas ferramentas de Inteligência Artificial | C4: Totalmente importante | D4: Muito forte | E4: Melhora muito | F4: =IF(ISERROR(VLOOKUP(C4,$H$6:$I$10,2,FALSE)*VLOOKUP(D4,$H$14:$I$18,2,FALSE)*VLOOKUP(E4,$H$22:$I$26,2,FALSE)),"",VLOOKUP(C4,$H$6:$I$10,2,FALSE)*VLOOKUP(D4,$H$14:$I$18,2,FALSE)*VLOOKUP(E4,$H$22:$I$26,2,FALSE)) -> 25 | H4: Importância | K4: 0.0002 | L4: =IF(F4="","",F4+K4) -> 25.0002 | M4: =IF(B4=0,"",B4) -> Rápida evolução e surgimento de novas ferramentas de Inteligência Artificial | N4: =F4 -> 25
B5: Crescimento da necessidade de plataformas de Governança de Dados e IA | C5: Totalmente importante | D5: Muito forte | E5: Melhora muito | F5: =IF(ISERROR(VLOOKUP(C5,$H$6:$I$10,2,FALSE)*VLOOKUP(D5,$H$14:$I$18,2,FALSE)*VLOOKUP(E5,$H$22:$I$26,2,FALSE)),"",VLOOKUP(C5,$H$6:$I$10,2,FALSE)*VLOOKUP(D5,$H$14:$I$18,2,FALSE)*VLOOKUP(E5,$H$22:$I$26,2,FALSE)) -> 25 | K5: 0.00019 | L5: =IF(F5="","",F5+K5) -> 25.00019 | M5: =IF(B5=0,"",B5) -> Crescimento da necessidade de plataformas de Governança de Dados e IA | N5: =F5 -> 25
B6: Evolução dos ecossistemas de Cloud e Data Lakehouses (Databricks, Snowflake) | C6: Importante | D6: Forte | E6: Melhora | F6: =IF(ISERROR(VLOOKUP(C6,$H$6:$I$10,2,FALSE)*VLOOKUP(D6,$H$14:$I$18,2,FALSE)*VLOOKUP(E6,$H$22:$I$26,2,FALSE)),"",VLOOKUP(C6,$H$6:$I$10,2,FALSE)*VLOOKUP(D6,$H$14:$I$18,2,FALSE)*VLOOKUP(E6,$H$22:$I$26,2,FALSE)) -> 24 | H6: Sem importância | I6: 1 | K6: 0.00018 | L6: =IF(F6="","",F6+K6) -> 24.00018 | M6: =IF(B6=0,"",B6) -> Evolução dos ecossistemas de Cloud e Data Lakehouses (Databricks, Snowflake) | N6: =F6 -> 24
B7: Aumento da complexidade na integração de múltiplas plataformas (Salesforce, Oracle, etc.) | C7: Importante | D7: Forte | E7: Piora | F7: =IF(ISERROR(VLOOKUP(C7,$H$6:$I$10,2,FALSE)*VLOOKUP(D7,$H$14:$I$18,2,FALSE)*VLOOKUP(E7,$H$22:$I$26,2,FALSE)),"",VLOOKUP(C7,$H$6:$I$10,2,FALSE)*VLOOKUP(D7,$H$14:$I$18,2,FALSE)*VLOOKUP(E7,$H$22:$I$26,2,FALSE)) -> 48 | H7: Pouco importante | I7: 2 | K7: 0.00017 | L7: =IF(F7="","",F7+K7) -> 48.00017 | M7: =IF(B7=0,"",B7) -> Aumento da complexidade na integração de múltiplas plataformas (Salesforce, Oracle, etc.) | N7: =F7 -> 48
B8: Democratização do Self-Service BI exigindo mais controle e monitoramento | C8: Importante | D8: Média | E8: Melhora | F8: =IF(ISERROR(VLOOKUP(C8,$H$6:$I$10,2,FALSE)*VLOOKUP(D8,$H$14:$I$18,2,FALSE)*VLOOKUP(E8,$H$22:$I$26,2,FALSE)),"",VLOOKUP(C8,$H$6:$I$10,2,FALSE)*VLOOKUP(D8,$H$14:$I$18,2,FALSE)*VLOOKUP(E8,$H$22:$I$26,2,FALSE)) -> 18 | H8: Importante | I8: 3 | K8: 0.00016 | L8: =IF(F8="","",F8+K8) -> 18.00016 | M8: =IF(B8=0,"",B8) -> Democratização do Self-Service BI exigindo mais controle e monitoramento | N8: =F8 -> 18
B9: Automação de pipelines de dados, Machine Learning e DataOps | C9: Sem importância | D9: Média | E9: Melhora | F9: =IF(ISERROR(VLOOKUP(C9,$H$6:$I$10,2,FALSE)*VLOOKUP(D9,$H$14:$I$18,2,FALSE)*VLOOKUP(E9,$H$22:$I$26,2,FALSE)),"",VLOOKUP(C9,$H$6:$I$10,2,FALSE)*VLOOKUP(D9,$H$14:$I$18,2,FALSE)*VLOOKUP(E9,$H$22:$I$26,2,FALSE)) -> 6 | H9: Muito importante | I9: 4 | K9: 0.00015 | L9: =IF(F9="","",F9+K9) -> 6.00015 | M9: =IF(B9=0,"",B9) -> Automação de pipelines de dados, Machine Learning e DataOps | N9: =F9 -> 6
B10: Avanços em cibersegurança para mitigar riscos de ferramentas não homologadas | C10: Sem importância | D10: Média | E10: Melhora | F10: =IF(ISERROR(VLOOKUP(C10,$H$6:$I$10,2,FALSE)*VLOOKUP(D10,$H$14:$I$18,2,FALSE)*VLOOKUP(E10,$H$22:$I$26,2,FALSE)),"",VLOOKUP(C10,$H$6:$I$10,2,FALSE)*VLOOKUP(D10,$H$14:$I$18,2,FALSE)*VLOOKUP(E10,$H$22:$I$26,2,FALSE)) -> 6 | H10: Totalmente importante | I10: 5 | K10: 0.00014 | L10: =IF(F10="","",F10+K10) -> 6.00014 | M10: =IF(B10=0,"",B10) -> Avanços em cibersegurança para mitigar riscos de ferramentas não homologadas | N10: =F10 -> 6
B11: Rápida obsolescência técnica de softwares e necessidade de atualização | C11: Sem importância | D11: Média | E11: Piora | F11: =IF(ISERROR(VLOOKUP(C11,$H$6:$I$10,2,FALSE)*VLOOKUP(D11,$H$14:$I$18,2,FALSE)*VLOOKUP(E11,$H$22:$I$26,2,FALSE)),"",VLOOKUP(C11,$H$6:$I$10,2,FALSE)*VLOOKUP(D11,$H$14:$I$18,2,FALSE)*VLOOKUP(E11,$H$22:$I$26,2,FALSE)) -> 12 | K11: 0.00013 | L11: =IF(F11="","",F11+K11) -> 12.00013 | M11: =IF(B11=0,"",B11) -> Rápida obsolescência técnica de softwares e necessidade de atualização | N11: =F11 -> 12
B12: Transição de ferramentas proprietárias para soluções baseadas em Open Source | C12: Pouco importante | D12: Fraca | E12: Mantém | F12: =IF(ISERROR(VLOOKUP(C12,$H$6:$I$10,2,FALSE)*VLOOKUP(D12,$H$14:$I$18,2,FALSE)*VLOOKUP(E12,$H$22:$I$26,2,FALSE)),"",VLOOKUP(C12,$H$6:$I$10,2,FALSE)*VLOOKUP(D12,$H$14:$I$18,2,FALSE)*VLOOKUP(E12,$H$22:$I$26,2,FALSE)) -> 12 | H12: Intensidade | K12: 0.00012 | L12: =IF(F12="","",F12+K12) -> 12.00012 | M12: =IF(B12=0,"",B12) -> Transição de ferramentas proprietárias para soluções baseadas em Open Source | N12: =F12 -> 12
B13: Avanços em Edge Computing e processamento descentralizado de dados | C13: Pouco importante | D13: Muito fraca | E13: Mantém | F13: =IF(ISERROR(VLOOKUP(C13,$H$6:$I$10,2,FALSE)*VLOOKUP(D13,$H$14:$I$18,2,FALSE)*VLOOKUP(E13,$H$22:$I$26,2,FALSE)),"",VLOOKUP(C13,$H$6:$I$10,2,FALSE)*VLOOKUP(D13,$H$14:$I$18,2,FALSE)*VLOOKUP(E13,$H$22:$I$26,2,FALSE)) -> 6 | K13: 0.00011 | L13: =IF(F13="","",F13+K13) -> 6.00011 | M13: =IF(B13=0,"",B13) -> Avanços em Edge Computing e processamento descentralizado de dados | N13: =F13 -> 6
F14: =IF(ISERROR(VLOOKUP(C14,$H$6:$I$10,2,FALSE)*VLOOKUP(D14,$H$14:$I$18,2,FALSE)*VLOOKUP(E14,$H$22:$I$26,2,FALSE)),"",VLOOKUP(C14,$H$6:$I$10,2,FALSE)*VLOOKUP(D14,$H$14:$I$18,2,FALSE)*VLOOKUP(E14,$H$22:$I$26,2,FALSE)) | H14: Muito forte | I14: 5 | K14: 0.0001 | L14: =IF(F14="","",F14+K14) | M14: =IF(B14=0,"",B14) | N14: =F14
F15: =IF(ISERROR(VLOOKUP(C15,$H$6:$I$10,2,FALSE)*VLOOKUP(D15,$H$14:$I$18,2,FALSE)*VLOOKUP(E15,$H$22:$I$26,2,FALSE)),"",VLOOKUP(C15,$H$6:$I$10,2,FALSE)*VLOOKUP(D15,$H$14:$I$18,2,FALSE)*VLOOKUP(E15,$H$22:$I$26,2,FALSE)) | H15: Forte | I15: 4 | K15: 9e-05 | L15: =IF(F15="","",F15+K15) | M15: =IF(B15=0,"",B15) | N15: =F15
F16: =IF(ISERROR(VLOOKUP(C16,$H$6:$I$10,2,FALSE)*VLOOKUP(D16,$H$14:$I$18,2,FALSE)*VLOOKUP(E16,$H$22:$I$26,2,FALSE)),"",VLOOKUP(C16,$H$6:$I$10,2,FALSE)*VLOOKUP(D16,$H$14:$I$18,2,FALSE)*VLOOKUP(E16,$H$22:$I$26,2,FALSE)) | H16: Média | I16: 3 | K16: 8e-05 | L16: =IF(F16="","",F16+K16) | M16: =IF(B16=0,"",B16) | N16: =F16
F17: =IF(ISERROR(VLOOKUP(C17,$H$6:$I$10,2,FALSE)*VLOOKUP(D17,$H$14:$I$18,2,FALSE)*VLOOKUP(E17,$H$22:$I$26,2,FALSE)),"",VLOOKUP(C17,$H$6:$I$10,2,FALSE)*VLOOKUP(D17,$H$14:$I$18,2,FALSE)*VLOOKUP(E17,$H$22:$I$26,2,FALSE)) | H17: Fraca | I17: 2 | K17: 7e-05 | L17: =IF(F17="","",F17+K17) | M17: =IF(B17=0,"",B17) | N17: =F17
F18: =IF(ISERROR(VLOOKUP(C18,$H$6:$I$10,2,FALSE)*VLOOKUP(D18,$H$14:$I$18,2,FALSE)*VLOOKUP(E18,$H$22:$I$26,2,FALSE)),"",VLOOKUP(C18,$H$6:$I$10,2,FALSE)*VLOOKUP(D18,$H$14:$I$18,2,FALSE)*VLOOKUP(E18,$H$22:$I$26,2,FALSE)) | H18: Muito fraca | I18: 1 | K18: 6e-05 | L18: =IF(F18="","",F18+K18) | M18: =IF(B18=0,"",B18) | N18: =F18
F19: =IF(ISERROR(VLOOKUP(C19,$H$6:$I$10,2,FALSE)*VLOOKUP(D19,$H$14:$I$18,2,FALSE)*VLOOKUP(E19,$H$22:$I$26,2,FALSE)),"",VLOOKUP(C19,$H$6:$I$10,2,FALSE)*VLOOKUP(D19,$H$14:$I$18,2,FALSE)*VLOOKUP(E19,$H$22:$I$26,2,FALSE)) | K19: 5e-05 | L19: =IF(F19="","",F19+K19) | M19: =IF(B19=0,"",B19) | N19: =F19
F20: =IF(ISERROR(VLOOKUP(C20,$H$6:$I$10,2,FALSE)*VLOOKUP(D20,$H$14:$I$18,2,FALSE)*VLOOKUP(E20,$H$22:$I$26,2,FALSE)),"",VLOOKUP(C20,$H$6:$I$10,2,FALSE)*VLOOKUP(D20,$H$14:$I$18,2,FALSE)*VLOOKUP(E20,$H$22:$I$26,2,FALSE)) | H20: Tendência | K20: 4e-05 | L20: =IF(F20="","",F20+K20) | M20: =IF(B20=0,"",B20) | N20: =F20
F21: =IF(ISERROR(VLOOKUP(C21,$H$6:$I$10,2,FALSE)*VLOOKUP(D21,$H$14:$I$18,2,FALSE)*VLOOKUP(E21,$H$22:$I$26,2,FALSE)),"",VLOOKUP(C21,$H$6:$I$10,2,FALSE)*VLOOKUP(D21,$H$14:$I$18,2,FALSE)*VLOOKUP(E21,$H$22:$I$26,2,FALSE)) | K21: 3e-05 | L21: =IF(F21="","",F21+K21) | M21: =IF(B21=0,"",B21) | N21: =F21
F22: =IF(ISERROR(VLOOKUP(C22,$H$6:$I$10,2,FALSE)*VLOOKUP(D22,$H$14:$I$18,2,FALSE)*VLOOKUP(E22,$H$22:$I$26,2,FALSE)),"",VLOOKUP(C22,$H$6:$I$10,2,FALSE)*VLOOKUP(D22,$H$14:$I$18,2,FALSE)*VLOOKUP(E22,$H$22:$I$26,2,FALSE)) | H22: Melhora muito | I22: 1 | K22: 2e-05 | L22: =IF(F22="","",F22+K22) | M22: =IF(B22=0,"",B22) | N22: =F22
F23: =IF(ISERROR(VLOOKUP(C23,$H$6:$I$10,2,FALSE)*VLOOKUP(D23,$H$14:$I$18,2,FALSE)*VLOOKUP(E23,$H$22:$I$26,2,FALSE)),"",VLOOKUP(C23,$H$6:$I$10,2,FALSE)*VLOOKUP(D23,$H$14:$I$18,2,FALSE)*VLOOKUP(E23,$H$22:$I$26,2,FALSE)) | H23: Melhora | I23: 2 | K23: 1e-05 | L23: =IF(F23="","",F23+K23) | M23: =IF(B23=0,"",B23) | N23: =F23
B24: Pontuação geral dos fatores tecnológicos | E24: → | F24: =SUM(F4:F23) -> 182 | H24: Mantém | I24: 3
H25: Piora | I25: 4
H26: Piora muito | I26: 5

Sheet Matriz
B5: 1.1 Top 5 Fatores Políticos | C5: =SUM(C6:C10) -> 317 | D5: 1.2 Top 5 Fatores Econômicos | E5: =SUM(E6:E10) -> 216 | G5: 0.0002 | H5: =IFERROR(G5+K5,"") -> 125.0002 | I5: =B6 -> Avanço da regulamentação da Inteligência Artificial no Brasil | J5: Político | K5: =C6 -> 125
A6: 1 | B6: =IF(ISERROR(VLOOKUP(LARGE('Fator Político'!$L$5:$L$24,$A6),'Fator Político'!$L$5:$M$24,2,FALSE)),"",VLOOKUP(LARGE('Fator Político'!$L$5:$L$24,$A6),'Fator Político'!$L$5:$M$24,2,FALSE)) -> Avanço da regulamentação da Inteligência Artificial no Brasil | C6: =IF(ISERROR(VLOOKUP(LARGE('Fator Político'!$L$5:$L$24,$A6),'Fator Político'!$L$5:$N$24,3,FALSE)),"",VLOOKUP(LARGE('Fator Político'!$L$5:$L$24,$A6),'Fator Político'!$L$5:$N$24,3,FALSE)) -> 125 | D6: =IF(ISERROR(VLOOKUP(LARGE('Fator Econômico'!$L$4:$L$23,$A6),'Fator Econômico'!$L$4:$M$23,2,FALSE)),"",VLOOKUP(LARGE('Fator Econômico'!$L$4:$L$23,$A6),'Fator Econômico'!$L$4:$M$23,2,FALSE)) -> Variação cambial (Dólar) impactando licenças de Cloud (AWS, Azure, etc.) | E6: =IF(ISERROR(VLOOKUP(LARGE('Fator Econômico'!$L$4:$L$23,$A6),'Fator Econômico'!$L$4:$N$23,3,FALSE)),"",VLOOKUP(LARGE('Fator Econômico'!$L$4:$L$23,$A6),'Fator Econômico'!$L$4:$N$23,3,FALSE)) -> 100 | G6: 0.00019 | H6: =IFERROR(G6+K6,"") -> 75.00019 | I6: =B7 -> Regulamentação e fiscalização da LGPD no uso de dados corporativos | J6: Político | K6: =C7 -> 75
A7: 2 | B7: =IF(ISERROR(VLOOKUP(LARGE('Fator Político'!$L$5:$L$24,$A7),'Fator Político'!$L$5:$M$24,2,FALSE)),"",VLOOKUP(LARGE('Fator Político'!$L$5:$L$24,$A7),'Fator Político'!$L$5:$M$24,2,FALSE)) -> Regulamentação e fiscalização da LGPD no uso de dados corporativos | C7: =IF(ISERROR(VLOOKUP(LARGE('Fator Político'!$L$5:$L$24,$A7),'Fator Político'!$L$5:$N$24,3,FALSE)),"",VLOOKUP(LARGE('Fator Político'!$L$5:$L$24,$A7),'Fator Político'!$L$5:$N$24,3,FALSE)) -> 75 | D7: =IF(ISERROR(VLOOKUP(LARGE('Fator Econômico'!$L$4:$L$23,$A7),'Fator Econômico'!$L$4:$M$23,2,FALSE)),"",VLOOKUP(LARGE('Fator Econômico'!$L$4:$L$23,$A7),'Fator Econômico'!$L$4:$M$23,2,FALSE)) -> Inflação salarial e custo para atração/retenção de talentos de TI | E7: =IF(ISERROR(VLOOKUP(LARGE('Fator Econômico'!$L$4:$L$23,$A7),'Fator Econômico'!$L$4:$N$23,3,FALSE)),"",VLOOKUP(LARGE('Fator Econômico'!$L$4:$L$23,$A7),'Fator Econômico'!$L$4:$N$23,3,FALSE)) -> 48 | G7: 0.00018 | H7: =IFERROR(G7+K7,"") -> 48.00018 | I7: =B8 -> Tributação sobre serviços de tecnologia e computação em nuvem | J7: Político | K7: =C8 -> 48
A8: 3 | B8: =IF(ISERROR(VLOOKUP(LARGE('Fator Político'!$L$5:$L$24,$A8),'Fator Político'!$L$5:$M$24,2,FALSE)),"",VLOOKUP(LARGE('Fator Político'!$L$5:$L$24,$A8),'Fator Político'!$L$5:$M$24,2,FALSE)) -> Tributação sobre serviços de tecnologia e computação em nuvem | C8: =IF(ISERROR(VLOOKUP(LARGE('Fator Político'!$L$5:$L$24,$A8),'Fator Político'!$L$5:$N$24,3,FALSE)),"",VLOOKUP(LARGE('Fator Político'!$L$5:$L$24,$A8),'Fator Político'!$L$5:$N$24,3,FALSE)) -> 48 | D8: =IF(ISERROR(VLOOKUP(LARGE('Fator Econômico'!$L$4:$L$23,$A8),'Fator Econômico'!$L$4:$M$23,2,FALSE)),"",VLOOKUP(LARGE('Fator Econômico'!$L$4:$L$23,$A8),'Fator Econômico'!$L$4:$M$23,2,FALSE)) -> Competitividade e pressão sobre o pricing de consultorias de dados | E8: =IF(ISERROR(VLOOKUP(LARGE('Fator Econômico'!$L$4:$L$23,$A8),'Fator Econômico'!$L$4:$N$23,3,FALSE)),"",VLOOKUP(LARGE('Fator Econômico'!$L$4:$L$23,$A8),'Fator Econômico'!$L$4:$N$23,3,FALSE)) -> 36 | G8: 0.00017 | H8: =IFERROR(G8+K8,"") -> 45.00017 | I8: =B9 -> Regras sobre transferência internacional de dados (Cloud) | J8: Político | K8: =C9 -> 45
A9: 4 | B9: =IF(ISERROR(VLOOKUP(LARGE('Fator Político'!$L$5:$L$24,$A9),'Fator Político'!$L$5:$M$24,2,FALSE)),"",VLOOKUP(LARGE('Fator Político'!$L$5:$L$24,$A9),'Fator Político'!$L$5:$M$24,2,FALSE)) -> Regras sobre transferência internacional de dados (Cloud) | C9: =IF(ISERROR(VLOOKUP(LARGE('Fator Político'!$L$5:$L$24,$A9),'Fator Político'!$L$5:$N$24,3,FALSE)),"",VLOOKUP(LARGE('Fator Político'!$L$5:$L$24,$A9),'Fator Político'!$L$5:$N$24,3,FALSE)) -> 45 | D9: =IF(ISERROR(VLOOKUP(LARGE('Fator Econômico'!$L$4:$L$23,$A9),'Fator Econômico'!$L$4:$M$23,2,FALSE)),"",VLOOKUP(LARGE('Fator Econômico'!$L$4:$L$23,$A9),'Fator Econômico'!$L$4:$M$23,2,FALSE)) -> Crescimento de investimentos tecnológicos no Setor Financeiro e Seguradoras | E9: =IF(ISERROR(VLOOKUP(LARGE('Fator Econômico'!$L$4:$L$23,$A9),'Fator Econômico'!$L$4:$N$23,3,FALSE)),"",VLOOKUP(LARGE('Fator Econômico'!$L$4:$L$23,$A9),'Fator Econômico'!$L$4:$N$23,3,FALSE)) -> 20 | G9: 0.00016 | H9: =IFERROR(G9+K9,"") -> 24.00016 | I9: =B10 -> Marcos regulatórios e de compliance no setor financeiro | J9: Político | K9: =C10 -> 24
A10: 5 | B10: =IF(ISERROR(VLOOKUP(LARGE('Fator Político'!$L$5:$L$24,$A10),'Fator Político'!$L$5:$M$24,2,FALSE)),"",VLOOKUP(LARGE('Fator Político'!$L$5:$L$24,$A10),'Fator Político'!$L$5:$M$24,2,FALSE)) -> Marcos regulatórios e de compliance no setor financeiro | C10: =IF(ISERROR(VLOOKUP(LARGE('Fator Político'!$L$5:$L$24,$A10),'Fator Político'!$L$5:$N$24,3,FALSE)),"",VLOOKUP(LARGE('Fator Político'!$L$5:$L$24,$A10),'Fator Político'!$L$5:$N$24,3,FALSE)) -> 24 | D10: =IF(ISERROR(VLOOKUP(LARGE('Fator Econômico'!$L$4:$L$23,$A10),'Fator Econômico'!$L$4:$M$23,2,FALSE)),"",VLOOKUP(LARGE('Fator Econômico'!$L$4:$L$23,$A10),'Fator Econômico'!$L$4:$M$23,2,FALSE)) -> Orçamento corporativo focado em eficiência e redução de custos (FinOps) | E10: =IF(ISERROR(VLOOKUP(LARGE('Fator Econômico'!$L$4:$L$23,$A10),'Fator Econômico'!$L$4:$N$23,3,FALSE)),"",VLOOKUP(LARGE('Fator Econômico'!$L$4:$L$23,$A10),'Fator Econômico'!$L$4:$N$23,3,FALSE)) -> 12 | G10: 0.00015 | H10: =IFERROR(G10+K10,"") -> 100.00015 | I10: =D6 -> Variação cambial (Dólar) impactando licenças de Cloud (AWS, Azure, etc.) | J10: Econômico | K10: =E6 -> 100
G11: 0.00014 | H11: =IFERROR(G11+K11,"") -> 48.00014 | I11: =D7 -> Inflação salarial e custo para atração/retenção de talentos de TI | J11: Econômico | K11: =E7 -> 48
G12: 0.00013 | H12: =IFERROR(G12+K12,"") -> 36.00013 | I12: =D8 -> Competitividade e pressão sobre o pricing de consultorias de dados | J12: Econômico | K12: =E8 -> 36
B13: 2.3 Top 5 Fatores Sociais | C13: =SUM(C14:C18) -> 287 | D13: 2.4 Top 5 Fatores Tecnológicos | E13: =SUM(E14:E18) -> 140 | G13: 0.00012 | H13: =IFERROR(G13+K13,"") -> 20.00012 | I13: =D9 -> Crescimento de investimentos tecnológicos no Setor Financeiro e Seguradoras | J13: Econômico | K13: =E9 -> 20
A14: 1 | B14: =IF(ISERROR(VLOOKUP(LARGE('Fator Social'!$L$4:$L$23,$A6),'Fator Social'!$L$4:$M$23,2,FALSE)),"",VLOOKUP(LARGE('Fator Social'!$L$4:$L$23,$A6),'Fator Social'!$L$4:$M$23,2,FALSE)) -> Adoção descontrolada de ferramentas de IA pelos funcionários (Shadow AI) | C14: =IF(ISERROR(VLOOKUP(LARGE('Fator Social'!$L$4:$L$23,$A6),'Fator Social'!$L$4:$N$23,3,FALSE)),"",VLOOKUP(LARGE('Fator Social'!$L$4:$L$23,$A6),'Fator Social'!$L$4:$N$23,3,FALSE)) -> 125 | D14: =IF(ISERROR(VLOOKUP(LARGE('Fator Tecnológico'!$L$4:$L$23,$A6),'Fator Tecnológico'!$L$4:$M$23,2,FALSE)),"",VLOOKUP(LARGE('Fator Tecnológico'!$L$4:$L$23,$A6),'Fator Tecnológico'!$L$4:$M$23,2,FALSE)) -> Aumento da complexidade na integração de múltiplas plataformas (Salesforce, Oracle, etc.) | E14: =IF(ISERROR(VLOOKUP(LARGE('Fator Tecnológico'!$L$4:$L$23,$A6),'Fator Tecnológico'!$L$4:$N$23,3,FALSE)),"",VLOOKUP(LARGE('Fator Tecnológico'!$L$4:$L$23,$A6),'Fator Tecnológico'!$L$4:$N$23,3,FALSE)) -> 48 | G14: 0.00011 | H14: =IFERROR(G14+K14,"") -> 12.00011 | I14: =D10 -> Orçamento corporativo focado em eficiência e redução de custos (FinOps) | J14: Econômico | K14: =E10 -> 12
A15: 2 | B15: =IF(ISERROR(VLOOKUP(LARGE('Fator Social'!$L$4:$L$23,$A7),'Fator Social'!$L$4:$M$23,2,FALSE)),"",VLOOKUP(LARGE('Fator Social'!$L$4:$L$23,$A7),'Fator Social'!$L$4:$M$23,2,FALSE)) -> Escassez de mão de obra superespecializada em dados e IA no mercado | C15: =IF(ISERROR(VLOOKUP(LARGE('Fator Social'!$L$4:$L$23,$A7),'Fator Social'!$L$4:$N$23,3,FALSE)),"",VLOOKUP(LARGE('Fator Social'!$L$4:$L$23,$A7),'Fator Social'!$L$4:$N$23,3,FALSE)) -> 80 | D15: =IF(ISERROR(VLOOKUP(LARGE('Fator Tecnológico'!$L$4:$L$23,$A7),'Fator Tecnológico'!$L$4:$M$23,2,FALSE)),"",VLOOKUP(LARGE('Fator Tecnológico'!$L$4:$L$23,$A7),'Fator Tecnológico'!$L$4:$M$23,2,FALSE)) -> Rápida evolução e surgimento de novas ferramentas de Inteligência Artificial | E15: =IF(ISERROR(VLOOKUP(LARGE('Fator Tecnológico'!$L$4:$L$23,$A7),'Fator Tecnológico'!$L$4:$N$23,3,FALSE)),"",VLOOKUP(LARGE('Fator Tecnológico'!$L$4:$L$23,$A7),'Fator Tecnológico'!$L$4:$N$23,3,FALSE)) -> 25 | G15: 0.0001 | H15: =IFERROR(G15+K15,"") -> 125.0001 | I15: =B14 -> Adoção descontrolada de ferramentas de IA pelos funcionários (Shadow AI) | J15: Social | K15: =C14 -> 125
A16: 3 | B16: =IF(ISERROR(VLOOKUP(LARGE('Fator Social'!$L$4:$L$23,$A8),'Fator Social'!$L$4:$M$23,2,FALSE)),"",VLOOKUP(LARGE('Fator Social'!$L$4:$L$23,$A8),'Fator Social'!$L$4:$M$23,2,FALSE)) -> Preocupação crescente com a privacidade e vazamento de dados corporativos | C16: =IF(ISERROR(VLOOKUP(LARGE('Fator Social'!$L$4:$L$23,$A8),'Fator Social'!$L$4:$N$23,3,FALSE)),"",VLOOKUP(LARGE('Fator Social'!$L$4:$L$23,$A8),'Fator Social'!$L$4:$N$23,3,FALSE)) -> 48 | D16: =IF(ISERROR(VLOOKUP(LARGE('Fator Tecnológico'!$L$4:$L$23,$A8),'Fator Tecnológico'!$L$4:$M$23,2,FALSE)),"",VLOOKUP(LARGE('Fator Tecnológico'!$L$4:$L$23,$A8),'Fator Tecnológico'!$L$4:$M$23,2,FALSE)) -> Crescimento da necessidade de plataformas de Governança de Dados e IA | E16: =IF(ISERROR(VLOOKUP(LARGE('Fator Tecnológico'!$L$4:$L$23,$A8),'Fator Tecnológico'!$L$4:$N$23,3,FALSE)),"",VLOOKUP(LARGE('Fator Tecnológico'!$L$4:$L$23,$A8),'Fator Tecnológico'!$L$4:$N$23,3,FALSE)) -> 25 | G16: 9e-05 | H16: =IFERROR(G16+K16,"") -> 80.00009 | I16: =B15 -> Escassez de mão de obra superespecializada em dados e IA no mercado | J16: Social | K16: =C15 -> 80
A17: 4 | B17: =IF(ISERROR(VLOOKUP(LARGE('Fator Social'!$L$4:$L$23,$A9),'Fator Social'!$L$4:$M$23,2,FALSE)),"",VLOOKUP(LARGE('Fator Social'!$L$4:$L$23,$A9),'Fator Social'!$L$4:$M$23,2,FALSE)) -> Necessidade contínua de capacitação das equipes (Lifelong learning) | C17: =IF(ISERROR(VLOOKUP(LARGE('Fator Social'!$L$4:$L$23,$A9),'Fator Social'!$L$4:$N$23,3,FALSE)),"",VLOOKUP(LARGE('Fator Social'!$L$4:$L$23,$A9),'Fator Social'!$L$4:$N$23,3,FALSE)) -> 18 | D17: =IF(ISERROR(VLOOKUP(LARGE('Fator Tecnológico'!$L$4:$L$23,$A9),'Fator Tecnológico'!$L$4:$M$23,2,FALSE)),"",VLOOKUP(LARGE('Fator Tecnológico'!$L$4:$L$23,$A9),'Fator Tecnológico'!$L$4:$M$23,2,FALSE)) -> Evolução dos ecossistemas de Cloud e Data Lakehouses (Databricks, Snowflake) | E17: =IF(ISERROR(VLOOKUP(LARGE('Fator Tecnológico'!$L$4:$L$23,$A9),'Fator Tecnológico'!$L$4:$N$23,3,FALSE)),"",VLOOKUP(LARGE('Fator Tecnológico'!$L$4:$L$23,$A9),'Fator Tecnológico'!$L$4:$N$23,3,FALSE)) -> 24 | G17: 8e-05 | H17: =IFERROR(G17+K17,"") -> 48.00008 | I17: =B16 -> Preocupação crescente com a privacidade e vazamento de dados corporativos | J17: Social | K17: =C16 -> 48
A18: 5 | B18: =IF(ISERROR(VLOOKUP(LARGE('Fator Social'!$L$4:$L$23,$A10),'Fator Social'!$L$4:$M$23,2,FALSE)),"",VLOOKUP(LARGE('Fator Social'!$L$4:$L$23,$A10),'Fator Social'!$L$4:$M$23,2,FALSE)) -> Resistência social e medo da substituição de empregos por Inteligência Artificial | C18: =IF(ISERROR(VLOOKUP(LARGE('Fator Social'!$L$4:$L$23,$A10),'Fator Social'!$L$4:$N$23,3,FALSE)),"",VLOOKUP(LARGE('Fator Social'!$L$4:$L$23,$A10),'Fator Social'!$L$4:$N$23,3,FALSE)) -> 16 | D18: =IF(ISERROR(VLOOKUP(LARGE('Fator Tecnológico'!$L$4:$L$23,$A10),'Fator Tecnológico'!$L$4:$M$23,2,FALSE)),"",VLOOKUP(LARGE('Fator Tecnológico'!$L$4:$L$23,$A10),'Fator Tecnológico'!$L$4:$M$23,2,FALSE)) -> Democratização do Self-Service BI exigindo mais controle e monitoramento | E18: =IF(ISERROR(VLOOKUP(LARGE('Fator Tecnológico'!$L$4:$L$23,$A10),'Fator Tecnológico'!$L$4:$N$23,3,FALSE)),"",VLOOKUP(LARGE('Fator Tecnológico'!$L$4:$L$23,$A10),'Fator Tecnológico'!$L$4:$N$23,3,FALSE)) -> 18 | G18: 7e-05 | H18: =IFERROR(G18+K18,"") -> 18.00007 | I18: =B17 -> Necessidade contínua de capacitação das equipes (Lifelong learning) | J18: Social | K18: =C17 -> 18
G19: 6e-05 | H19: =IFERROR(G19+K19,"") -> 16.00006 | I19: =B18 -> Resistência social e medo da substituição de empregos por Inteligência Artificial | J19: Social | K19: =C18 -> 16
G20: 5e-05 | H20: =IFERROR(G20+K20,"") -> 48.00005 | I20: =D14 -> Aumento da complexidade na integração de múltiplas plataformas (Salesforce, Oracle, etc.) | J20: Tecnológico | K20: =E14 -> 48
G21: 4e-05 | H21: =IFERROR(G21+K21,"") -> 25.00004 | I21: =D15 -> Rápida evolução e surgimento de novas ferramentas de Inteligência Artificial | J21: Tecnológico | K21: =E15 -> 25
G22: 3e-05 | H22: =IFERROR(G22+K22,"") -> 25.00003 | I22: =D16 -> Crescimento da necessidade de plataformas de Governança de Dados e IA | J22: Tecnológico | K22: =E16 -> 25
G23: 2e-05 | H23: =IFERROR(G23+K23,"") -> 24.00002 | I23: =D17 -> Evolução dos ecossistemas de Cloud e Data Lakehouses (Databricks, Snowflake) | J23: Tecnológico | K23: =E17 -> 24
G24: 1e-05 | H24: =IFERROR(G24+K24,"") -> 18.00001 | I24: =D18 -> Democratização do Self-Service BI exigindo mais controle e monitoramento | J24: Tecnológico | K24: =E18 -> 18

Sheet Planejamento
B3: Atividades Planejadas | C3: Fator Relacionado | D3: Fator PEST | E3: Líder | F3: Setor | G3: Iníco | H3: Término | I3: Etapa | J3: Andamento
B4: Atividades 1 | C4: Instabilidade política na câmara dos deputados | D4: =IF(ISERROR(VLOOKUP(C4,Matriz!$I$5:$J$24,2,FALSE)),"",VLOOKUP(C4,Matriz!$I$5:$J$24,2,FALSE)) | E4: Colaborador 1 | F4: =IF(E4=0,"",VLOOKUP(E4,Líderes!$B$4:$C$53,2,FALSE)) -> Financeiro | G4: 44197 | H4: 44226 | I4: Não Iniciado | J4: =IF(I4=0,"",IF(I4="Concluído","Concluído",IF(AND(TODAY()>H4,I4<>"Concluído"),"Atrasado",IF(AND(TODAY()<G4,I4="Não iniciado"),"Aguardando",IF(AND(TODAY()<G4,I4="Em andamento"),"Adiantado",IF(AND(TODAY()>=G4,TODAY()<=H4,I4="Em andamento"),"Em andamento","Atrasado")))))) -> Atrasado | L4: =Líderes!#REF! -> #REF!
B5: Atividades 2 | C5: Aumento das exportações | D5: =IF(ISERROR(VLOOKUP(C5,Matriz!$I$5:$J$24,2,FALSE)),"",VLOOKUP(C5,Matriz!$I$5:$J$24,2,FALSE)) | E5: Colaborador 2 | F5: =IF(E5=0,"",VLOOKUP(E5,Líderes!$B$4:$C$53,2,FALSE)) -> Operações | G5: 44198 | H5: 44227 | I5: Não Iniciado | J5: =IF(I5=0,"",IF(I5="Concluído","Concluído",IF(AND(TODAY()>H5,I5<>"Concluído"),"Atrasado",IF(AND(TODAY()<G5,I5="Não iniciado"),"Aguardando",IF(AND(TODAY()<G5,I5="Em andamento"),"Adiantado",IF(AND(TODAY()>=G5,TODAY()<=H5,I5="Em andamento"),"Em andamento","Atrasado")))))) -> Atrasado | L5: =Líderes!B4 -> Colaborador 1 | N5: 1 | O5: =IFERROR(VLOOKUP(LARGE(Matriz!$H$5:$H$24,$N5),Matriz!$H$5:$I$24,2,FALSE),"") -> Avanço da regulamentação da Inteligência Artificial no Brasil
B6: Atividades 3 | C6: Novo ministro da economia | D6: =IF(ISERROR(VLOOKUP(C6,Matriz!$I$5:$J$24,2,FALSE)),"",VLOOKUP(C6,Matriz!$I$5:$J$24,2,FALSE)) | E6: Colaborador 3 | F6: =IF(E6=0,"",VLOOKUP(E6,Líderes!$B$4:$C$53,2,FALSE)) -> Operações | G6: 44199 | H6: 44228 | I6: Em Andamento | J6: =IF(I6=0,"",IF(I6="Concluído","Concluído",IF(AND(TODAY()>H6,I6<>"Concluído"),"Atrasado",IF(AND(TODAY()<G6,I6="Não iniciado"),"Aguardando",IF(AND(TODAY()<G6,I6="Em andamento"),"Adiantado",IF(AND(TODAY()>=G6,TODAY()<=H6,I6="Em andamento"),"Em andamento","Atrasado")))))) -> Atrasado | L6: =Líderes!B5 -> Colaborador 2 | N6: 2 | O6: =IFERROR(VLOOKUP(LARGE(Matriz!$H$5:$H$24,$N6),Matriz!$H$5:$I$24,2,FALSE),"") -> Adoção descontrolada de ferramentas de IA pelos funcionários (Shadow AI)
B7: Atividades 4 | C7: Redução da taxa SELIC | D7: =IF(ISERROR(VLOOKUP(C7,Matriz!$I$5:$J$24,2,FALSE)),"",VLOOKUP(C7,Matriz!$I$5:$J$24,2,FALSE)) | E7: Colaborador 4 | F7: =IF(E7=0,"",VLOOKUP(E7,Líderes!$B$4:$C$53,2,FALSE)) -> Qualidade | G7: 44200 | H7: 44229 | I7: Em Andamento | J7: =IF(I7=0,"",IF(I7="Concluído","Concluído",IF(AND(TODAY()>H7,I7<>"Concluído"),"Atrasado",IF(AND(TODAY()<G7,I7="Não iniciado"),"Aguardando",IF(AND(TODAY()<G7,I7="Em andamento"),"Adiantado",IF(AND(TODAY()>=G7,TODAY()<=H7,I7="Em andamento"),"Em andamento","Atrasado")))))) -> Atrasado | L7: =Líderes!B6 -> Colaborador 3 | N7: 3 | O7: =IFERROR(VLOOKUP(LARGE(Matriz!$H$5:$H$24,$N7),Matriz!$H$5:$I$24,2,FALSE),"") -> Variação cambial (Dólar) impactando licenças de Cloud (AWS, Azure, etc.)
D8: =IF(ISERROR(VLOOKUP(C8,Matriz!$I$5:$J$24,2,FALSE)),"",VLOOKUP(C8,Matriz!$I$5:$J$24,2,FALSE)) | F8: =IF(E8=0,"",VLOOKUP(E8,Líderes!$B$4:$C$53,2,FALSE)) | J8: =IF(I8=0,"",IF(I8="Concluído","Concluído",IF(AND(TODAY()>H8,I8<>"Concluído"),"Atrasado",IF(AND(TODAY()<G8,I8="Não iniciado"),"Aguardando",IF(AND(TODAY()<G8,I8="Em andamento"),"Adiantado",IF(AND(TODAY()>=G8,TODAY()<=H8,I8="Em andamento"),"Em andamento","Atrasado")))))) | L8: =Líderes!B7 -> Colaborador 4 | N8: 4 | O8: =IFERROR(VLOOKUP(LARGE(Matriz!$H$5:$H$24,$N8),Matriz!$H$5:$I$24,2,FALSE),"") -> Escassez de mão de obra superespecializada em dados e IA no mercado
D9: =IF(ISERROR(VLOOKUP(C9,Matriz!$I$5:$J$24,2,FALSE)),"",VLOOKUP(C9,Matriz!$I$5:$J$24,2,FALSE)) | F9: =IF(E9=0,"",VLOOKUP(E9,Líderes!$B$4:$C$53,2,FALSE)) | J9: =IF(I9=0,"",IF(I9="Concluído","Concluído",IF(AND(TODAY()>H9,I9<>"Concluído"),"Atrasado",IF(AND(TODAY()<G9,I9="Não iniciado"),"Aguardando",IF(AND(TODAY()<G9,I9="Em andamento"),"Adiantado",IF(AND(TODAY()>=G9,TODAY()<=H9,I9="Em andamento"),"Em andamento","Atrasado")))))) | L9: =Líderes!B8 -> Colaborador 5 | N9: 5 | O9: =IFERROR(VLOOKUP(LARGE(Matriz!$H$5:$H$24,$N9),Matriz!$H$5:$I$24,2,FALSE),"") -> Regulamentação e fiscalização da LGPD no uso de dados corporativos
D10: =IF(ISERROR(VLOOKUP(C10,Matriz!$I$5:$J$24,2,FALSE)),"",VLOOKUP(C10,Matriz!$I$5:$J$24,2,FALSE)) | F10: =IF(E10=0,"",VLOOKUP(E10,Líderes!$B$4:$C$53,2,FALSE)) | J10: =IF(I10=0,"",IF(I10="Concluído","Concluído",IF(AND(TODAY()>H10,I10<>"Concluído"),"Atrasado",IF(AND(TODAY()<G10,I10="Não iniciado"),"Aguardando",IF(AND(TODAY()<G10,I10="Em andamento"),"Adiantado",IF(AND(TODAY()>=G10,TODAY()<=H10,I10="Em andamento"),"Em andamento","Atrasado")))))) | L10: =Líderes!B9 -> Colaborador 6 | N10: 6 | O10: =IFERROR(VLOOKUP(LARGE(Matriz!$H$5:$H$24,$N10),Matriz!$H$5:$I$24,2,FALSE),"") -> Tributação sobre serviços de tecnologia e computação em nuvem
D11: =IF(ISERROR(VLOOKUP(C11,Matriz!$I$5:$J$24,2,FALSE)),"",VLOOKUP(C11,Matriz!$I$5:$J$24,2,FALSE)) | F11: =IF(E11=0,"",VLOOKUP(E11,Líderes!$B$4:$C$53,2,FALSE)) | J11: =IF(I11=0,"",IF(I11="Concluído","Concluído",IF(AND(TODAY()>H11,I11<>"Concluído"),"Atrasado",IF(AND(TODAY()<G11,I11="Não iniciado"),"Aguardando",IF(AND(TODAY()<G11,I11="Em andamento"),"Adiantado",IF(AND(TODAY()>=G11,TODAY()<=H11,I11="Em andamento"),"Em andamento","Atrasado")))))) | L11: =Líderes!B10 -> 0 | N11: 7 | O11: =IFERROR(VLOOKUP(LARGE(Matriz!$H$5:$H$24,$N11),Matriz!$H$5:$I$24,2,FALSE),"") -> Inflação salarial e custo para atração/retenção de talentos de TI
D12: =IF(ISERROR(VLOOKUP(C12,Matriz!$I$5:$J$24,2,FALSE)),"",VLOOKUP(C12,Matriz!$I$5:$J$24,2,FALSE)) | F12: =IF(E12=0,"",VLOOKUP(E12,Líderes!$B$4:$C$53,2,FALSE)) | J12: =IF(I12=0,"",IF(I12="Concluído","Concluído",IF(AND(TODAY()>H12,I12<>"Concluído"),"Atrasado",IF(AND(TODAY()<G12,I12="Não iniciado"),"Aguardando",IF(AND(TODAY()<G12,I12="Em andamento"),"Adiantado",IF(AND(TODAY()>=G12,TODAY()<=H12,I12="Em andamento"),"Em andamento","Atrasado")))))) | L12: =Líderes!B11 -> 0 | N12: 8 | O12: =IFERROR(VLOOKUP(LARGE(Matriz!$H$5:$H$24,$N12),Matriz!$H$5:$I$24,2,FALSE),"") -> Preocupação crescente com a privacidade e vazamento de dados corporativos
D13: =IF(ISERROR(VLOOKUP(C13,Matriz!$I$5:$J$24,2,FALSE)),"",VLOOKUP(C13,Matriz!$I$5:$J$24,2,FALSE)) | F13: =IF(E13=0,"",VLOOKUP(E13,Líderes!$B$4:$C$53,2,FALSE)) | J13: =IF(I13=0,"",IF(I13="Concluído","Concluído",IF(AND(TODAY()>H13,I13<>"Concluído"),"Atrasado",IF(AND(TODAY()<G13,I13="Não iniciado"),"Aguardando",IF(AND(TODAY()<G13,I13="Em andamento"),"Adiantado",IF(AND(TODAY()>=G13,TODAY()<=H13,I13="Em andamento"),"Em andamento","Atrasado")))))) | L13: =Líderes!B12 -> 0 | N13: 9 | O13: =IFERROR(VLOOKUP(LARGE(Matriz!$H$5:$H$24,$N13),Matriz!$H$5:$I$24,2,FALSE),"") -> Aumento da complexidade na integração de múltiplas plataformas (Salesforce, Oracle, etc.)
D14: =IF(ISERROR(VLOOKUP(C14,Matriz!$I$5:$J$24,2,FALSE)),"",VLOOKUP(C14,Matriz!$I$5:$J$24,2,FALSE)) | F14: =IF(E14=0,"",VLOOKUP(E14,Líderes!$B$4:$C$53,2,FALSE)) | J14: =IF(I14=0,"",IF(I14="Concluído","Concluído",IF(AND(TODAY()>H14,I14<>"Concluído"),"Atrasado",IF(AND(TODAY()<G14,I14="Não iniciado"),"Aguardando",IF(AND(TODAY()<G14,I14="Em andamento"),"Adiantado",IF(AND(TODAY()>=G14,TODAY()<=H14,I14="Em andamento"),"Em andamento","Atrasado")))))) | L14: =Líderes!B13 -> 0 | N14: 10 | O14: =IFERROR(VLOOKUP(LARGE(Matriz!$H$5:$H$24,$N14),Matriz!$H$5:$I$24,2,FALSE),"") -> Regras sobre transferência internacional de dados (Cloud)
D15: =IF(ISERROR(VLOOKUP(C15,Matriz!$I$5:$J$24,2,FALSE)),"",VLOOKUP(C15,Matriz!$I$5:$J$24,2,FALSE)) | F15: =IF(E15=0,"",VLOOKUP(E15,Líderes!$B$4:$C$53,2,FALSE)) | J15: =IF(I15=0,"",IF(I15="Concluído","Concluído",IF(AND(TODAY()>H15,I15<>"Concluído"),"Atrasado",IF(AND(TODAY()<G15,I15="Não iniciado"),"Aguardando",IF(AND(TODAY()<G15,I15="Em andamento"),"Adiantado",IF(AND(TODAY()>=G15,TODAY()<=H15,I15="Em andamento"),"Em andamento","Atrasado")))))) | L15: =Líderes!B14 -> 0 | N15: 11 | O15: =IFERROR(VLOOKUP(LARGE(Matriz!$H$5:$H$24,$N15),Matriz!$H$5:$I$24,2,FALSE),"") -> Competitividade e pressão sobre o pricing de consultorias de dados
D16: =IF(ISERROR(VLOOKUP(C16,Matriz!$I$5:$J$24,2,FALSE)),"",VLOOKUP(C16,Matriz!$I$5:$J$24,2,FALSE)) | F16: =IF(E16=0,"",VLOOKUP(E16,Líderes!$B$4:$C$53,2,FALSE)) | J16: =IF(I16=0,"",IF(I16="Concluído","Concluído",IF(AND(TODAY()>H16,I16<>"Concluído"),"Atrasado",IF(AND(TODAY()<G16,I16="Não iniciado"),"Aguardando",IF(AND(TODAY()<G16,I16="Em andamento"),"Adiantado",IF(AND(TODAY()>=G16,TODAY()<=H16,I16="Em andamento"),"Em andamento","Atrasado")))))) | L16: =Líderes!B15 -> 0 | N16: 12 | O16: =IFERROR(VLOOKUP(LARGE(Matriz!$H$5:$H$24,$N16),Matriz!$H$5:$I$24,2,FALSE),"") -> Rápida evolução e surgimento de novas ferramentas de Inteligência Artificial
D17: =IF(ISERROR(VLOOKUP(C17,Matriz!$I$5:$J$24,2,FALSE)),"",VLOOKUP(C17,Matriz!$I$5:$J$24,2,FALSE)) | F17: =IF(E17=0,"",VLOOKUP(E17,Líderes!$B$4:$C$53,2,FALSE)) | J17: =IF(I17=0,"",IF(I17="Concluído","Concluído",IF(AND(TODAY()>H17,I17<>"Concluído"),"Atrasado",IF(AND(TODAY()<G17,I17="Não iniciado"),"Aguardando",IF(AND(TODAY()<G17,I17="Em andamento"),"Adiantado",IF(AND(TODAY()>=G17,TODAY()<=H17,I17="Em andamento"),"Em andamento","Atrasado")))))) | L17: =Líderes!B16 -> 0 | N17: 13 | O17: =IFERROR(VLOOKUP(LARGE(Matriz!$H$5:$H$24,$N17),Matriz!$H$5:$I$24,2,FALSE),"") -> Crescimento da necessidade de plataformas de Governança de Dados e IA
D18: =IF(ISERROR(VLOOKUP(C18,Matriz!$I$5:$J$24,2,FALSE)),"",VLOOKUP(C18,Matriz!$I$5:$J$24,2,FALSE)) | F18: =IF(E18=0,"",VLOOKUP(E18,Líderes!$B$4:$C$53,2,FALSE)) | J18: =IF(I18=0,"",IF(I18="Concluído","Concluído",IF(AND(TODAY()>H18,I18<>"Concluído"),"Atrasado",IF(AND(TODAY()<G18,I18="Não iniciado"),"Aguardando",IF(AND(TODAY()<G18,I18="Em andamento"),"Adiantado",IF(AND(TODAY()>=G18,TODAY()<=H18,I18="Em andamento"),"Em andamento","Atrasado")))))) | L18: =Líderes!B17 -> 0 | N18: 14 | O18: =IFERROR(VLOOKUP(LARGE(Matriz!$H$5:$H$24,$N18),Matriz!$H$5:$I$24,2,FALSE),"") -> Marcos regulatórios e de compliance no setor financeiro
